Workbook

Sheet LEEME
A1: MEMORIA DE CÁLCULO HIDRÁULICA — UNIDAD DE AUTOLAVADO
A2: Plantilla general editable. Las celdas azules son entradas, las verdes contienen fórmulas y las amarillas son supuestos provisionales o datos que requieren confirmación.
A4: Tema | B4: Instrucción
A5: Propósito | B5: Representar matemáticamente el recorrido hidráulico desde la acometida de agua hasta la boquilla, incluyendo pérdidas, calentamiento, bomba, inyector Venturi, manguera, pistola y descarga.
A6: Alcance del modelo | B6: Régimen estacionario e incompresible como primera iteración. No es un solucionador de redes ramificadas/paralelas ni calcula golpes de ariete o transitorios de cierre.
A7: Cómo empezar | B7: 1) Complete Datos_base; 2) introduzca datos de ficha en Bomba, Venturi y Boquilla; 3) complete longitud, diámetro interno y rugosidad en Tuberias; 4) introduzca pérdidas del filtro, calentador y pistola; 5) revise Resumen, Estaciones y Verificacion.
A8: Modo activo | B8: Datos_base!B5 permite elegir el caso que se calcula: Prelavado, Jabón, Enjuague, Cera o Pistola cerrada. La hoja Modos define valores iniciales por etapa. El caudal calculado usa el modo activo.
A9: Esquema flexible | B9: La hoja Tuberias permite hasta 20 tramos editables, con pocas curvas si ese es el diseño. No se necesita fijar ahora el trazado definitivo; cada tramo debe tener longitud, diámetro interno, rugosidad y suma de K explícitos (usar 0 solo cuando sea justificable).
A10: Presiones | B10: Las presiones de acometida y de descarga de bomba se manejan como manométricas (bar(g)); para NPSH se convierte a presión absoluta usando la presión atmosférica local editable.
A11: Curva de bomba | B11: La presión nominal/maximal y el caudal publicado para TRENT HLT395 no constituyen una curva Q–P verificada ni garantizan que esos datos ocurran simultáneamente. Los cálculos contra 110 bar son comparaciones preliminares, no un punto de operación certificado.
A12: Bloqueo crítico de temperatura | B12: La ficha de venta consultada para TRENT HLT395 indica temperatura máxima de agua de 50 °C, pero también «no apto para agua caliente». No alimentar agua calentada a la succión de esta unidad sin aprobación escrita del fabricante o cambio a un equipo apto para agua caliente.
A13: Venturi | B13: La página de AQB consultada describe el principio, pero no expone en el contenido disponible una referencia exacta con curvas de presión/caudal/aspiración. El modelo exige completar datos del fabricante o medirlos.
A14: Propiedades del agua | B14: La hoja Propiedades usa correlaciones aproximadas para agua líquida entre 0 y 100 °C (Antoine para presión de vapor). Para mezclas químicas, se aproxima inicialmente la propiedad de la mezcla a la del agua; confirmar si la formulación cambia significativamente densidad o viscosidad.
A15: Boquilla | B15: El método de orificio es una estimación con coeficiente de descarga Cd. La curva/tabla del fabricante tiene prioridad sobre este cálculo cuando esté disponible.
... A17: Seguridad y uso | B17: La memoria no sustituye validación de presión/temperatura nominal, selección de válvula de alivio, protección eléctrica, ensayos de estanqueidad ni revisión por personal competente.

Sheet Datos_base
A1: DATOS GENERALES Y CONDICIONES DE FRONTERA
A2: Complete los campos azules. Valores amarillos = supuestos o datos publicados que requieren validación.
A4: Parámetro | B4: Valor | C4: Unidad | D4: Tipo | E4: Fuente / criterio / observación
A5: Modo de operación activo | B5: Enjuague | C5: — | D5: Entrada | E5: Seleccione el caso a calcular en el desplegable.
A6: Aceleración gravitacional g | B6: 9.81 | C6: m/s² | D6: Constante editable | E6: Constante física estándar.
A7: Presión atmosférica local | B7: 74 | C7: kPa(abs) | D7: Supuesto editable | E7: Aproximación inicial para Bogotá; sustituir por presión barométrica del sitio.
A8: Presión dinámica de acometida | B8: 1.5 | C8: bar(g) | D8: Entrada requerida | E8: Medir en el punto real de conexión con caudal circulando; no usar presión estática sin flujo.
A9: Temperatura de agua de entrada | B9: 15 | C9: °C | D9: Supuesto editable | E9: Valor preliminar de arranque; medir en la instalación.
A10: Caudal de agua de referencia | B10: 7 | C10: L/min | D10: Dato publicado preliminar | E10: Listado de venta de HLT395 indica 7 L/min; confirmar ficha oficial y punto de operación.
A11: Calor específico del agua | B11: 4180 | C11: J/(kg·K) | D11: Supuesto editable | E11: Aproximación para agua líquida; puede actualizarse con datos más precisos.
A12: Temperatura objetivo a la salida del calentador | B12: 40 | C12: °C | D12: Entrada requerida | E12: No definir sin compatibilidad de bomba, mangueras, sellos, químicos y calentador.
A13: Diferencia de cota (superficie fuente − succión bomba) | B13: 0.5 | C13: m | D13: Supuesto editable | E13: Positivo si la superficie/centro de presión de la fuente está por encima de la brida de succión.
A14: Margen de presión de diseño | B14: 0.2 | C14: fracción | D14: Supuesto editable | E14: 20 % preliminar para comparación; confirmar según criterio de diseño. No reemplaza margen del fabricante.
A15: Reserva NPSH sobre NPSHr | B15: 3 | C15: m | D15: Entrada requerida | E15: Definir según fabricante, tipo de bomba y criterio de diseño.
A16: Potencia térmica nominal del calentador | B16: 12 | C16: kW | D16: Entrada requerida | E16: Registrar potencia útil disponible, no solo consumo eléctrico.
A17: Temperatura máxima de entrada publicada HLT395 | B17: 50 | C17: °C | D17: Dato no confirmado oficialmente | E17: La misma publicación consultada indica «no apto para agua caliente»; no interpretar 50 °C como autorización para precalentar.
A18: Densidad de agua a la entrada | B18: =Propiedades!B7 -> 999.12855 | C18: kg/m³ | D18: Calculado | E18: Correlación en hoja Propiedades.
A19: Viscosidad dinámica de agua a la entrada | B19: =Propiedades!B8 -> 0.0011359687 | C19: Pa·s | D19: Calculado | E19: Correlación en hoja Propiedades.
A20: Caudal activo de agua | B20: =IFERROR(INDEX(Modos!$D$5:$D$9,MATCH($B$5,Modos!$A$5:$A$9,0)),$B$10) -> 7 | C20: L/min | D20: Calculado | E20: Toma el caudal definido para el modo activo de la hoja Modos.
A21: Caudal activo de producto químico | B21: =IF($B$5="Pistola cerrada",0,IF(OR($B$5="Prelavado",$B$5="Jabón",$B$5="Cera"),IF(Venturi!$B$11="","",Venturi!$B$11),0)) -> 0 | C21: L/min | D21: Calculado | E21: Se activa solo para Prelavado, Jabón y Cera; requiere caudal de aspiración medido o de fabricante.
A22: Caudal total de mezcla | B22: =IF($B$5="Pistola cerrada",0,IF(OR($B$5="Prelavado",$B$5="Jabón",$B$5="Cera"),IF(Venturi!$B$11="","",B20+Venturi!$B$11),B20)) -> 7 | C22: L/min | D22: Calculado | E22: Suma caudal de agua y químico; en Enjuague equivale al caudal de agua.
A23: Temperatura estimada en succión de bomba | B23: =IF(B12="",B9,B12) -> 40 | C23: °C | D23: Calculado | E23: Si no se define temperatura objetivo, supone que no hay calentamiento (T de succión = T de entrada).

Sheet Modos
A1: MATRIZ DE MODOS DE OPERACIÓN
A2: Esta hoja define los parámetros por etapa. El caso seleccionado en Datos_base!B5 se utiliza en el cálculo integrado; para analizar otro modo, selecciónelo allí.
A4: Modo | B4: ¿Aspira químico? | C4: Producto | D4: Caudal agua objetivo (L/min) | E4: T objetivo (°C) | F4: Tiempo etapa (s) | G4: Estado pistola | H4: Configuración de boquilla | I4: Notas / verificación
A5: Prelavado | B5: Sí | C5: Prelavado | D5: =Datos_base!$B$10 -> 7 | E5: 40 | G5: Abierta | H5: 1.15 mm
A6: Jabón | B6: Sí | C6: Jabón / detergente | D6: =Datos_base!$B$10 -> 7 | E6: 40 | G6: Abierta | H6: 1.15 mm
A7: Enjuague | B7: No | C7: N/A | D7: =Datos_base!$B$10 -> 7 | E7: 40 | G7: Abierta | H7: 1.15 mm | I7: El Venturi sigue generando pérdida de presión aunque no aspire producto.
A8: Cera | B8: Sí | C8: Cera | D8: =Datos_base!$B$10 -> 7 | E8: 40 | G8: Abierta | H8: 1.15 mm
A9: Pistola cerrada | B9: No | C9: Ninguno | D9: 0 | E9: 0 | F9: 0 | G9: Cerrada | H9: No hay descarga | I9: Estado separado; no se simula transitorio, presión atrapada ni lógica del auto-stop.

Sheet Propiedades
A1: PROPIEDADES TERMOFÍSICAS DEL AGUA
A2: Correlaciones aproximadas para agua líquida. Validez de trabajo indicada en cada fila; sustituir por tablas oficiales si el cálculo exige mayor precisión.
A4: Propiedad | B4: Entrada / resultado | C4: Unidad | D4: Método | E4: Observación
A5: Temperatura agua a la entrada | B5: =Datos_base!B9 -> 15 | C5: °C | D5: Vínculo | E5: Enlace a Datos_base.
A6: Temperatura en succión de bomba | B6: =Datos_base!B23 -> 40 | C6: °C | D6: Vínculo | E6: Si no se define setpoint, usa temperatura de entrada.
A7: Densidad a T entrada | B7: =IF(OR(B5="",B5<0,B5>100),"",1000*(1-(((B5+288.9414)/(508929.2*(B5+68.12963)))*(B5-3.9863)^2))) -> 999.12855 | C7: kg/m³ | D7: Correlación empírica | E7: Aproximación de densidad de agua; rango 0–100 °C.
A8: Viscosidad dinámica a T entrada | B8: =IF(OR(B5="",B5<0,B5>100),"",0.00002414*10^(247.8/(B5+133.15))) -> 0.0011359687 | C8: Pa·s | D8: Correlación tipo Vogel | E8: Aproximación para agua líquida; rango 0–100 °C.
A9: Presión de vapor a T entrada | B9: =IF(OR(B5="",B5<1,B5>100),"",10^(8.07131-1730.63/(233.426+B5))*0.133322) -> 1.6975848 | C9: kPa(abs) | D9: Antoine | E9: La ecuación usada aplica aproximadamente entre 1 y 100 °C.
A10: Calor específico | B10: =Datos_base!B11 -> 4180 | C10: J/(kg·K) | D10: Dato editable | E10: Constante nominal; aproximación para agua líquida.
A12: Densidad a T succión | B12: =IF(OR(B6="",B6<0,B6>100),"",1000*(1-(((B6+288.9414)/(508929.2*(B6+68.12963)))*(B6-3.9863)^2))) -> 992.24732 | C12: kg/m³ | D12: Correlación empírica | E12: Usada para NPSH y como primera aproximación de mezcla.
A13: Viscosidad dinámica a T succión | B13: =IF(OR(B6="",B6<0,B6>100),"",0.00002414*10^(247.8/(B6+133.15))) -> 0.00065142788 | C13: Pa·s | D13: Correlación tipo Vogel | E13: Usada para Reynolds en tramos con agua/mezcla.
A14: Presión de vapor a T succión | B14: =IF(OR(B6="",B6<1,B6>100),"",10^(8.07131-1730.63/(233.426+B6))*0.133322) -> 7.3584184 | C14: kPa(abs) | D14: Antoine | E14: Crítica para calcular NPSH disponible.
A15: Calor específico a T succión | B15: =Datos_base!B11 -> 4180 | C15: J/(kg·K) | D15: Dato editable | E15: Vínculo al valor de Datos_base.

Sheet Bomba
A1: BOMBA / HIDROLAVADORA DE REFERENCIA
A2: Datos preliminares del equipo informado por el usuario y de un listado de venta consultado. Completar con ficha oficial, manual y curva de operación.
A4: Parámetro | B4: Valor | C4: Unidad | D4: Estado | E4: Fuente / observación
A5: Equipo | B5: TRENT HLT395 | C5: — | D5: Referencia suministrada | E5: Hidrolavadora completa; no se dispone todavía de curva de bomba aislada.
A6: Potencia eléctrica publicada | B6: 1800 | C6: W | D6: Dato publicado | E6: Listado de venta consultado; verificar placa del equipo.
A7: Presión nominal publicada | B7: 80 | C7: bar(g) | D7: Dato publicado | E7: No equivale a curva Q–P ni garantiza el punto de operación a 7 L/min.
A8: Presión máxima publicada | B8: 130 | C8: bar(g) | D8: Dato publicado | E8: Límite reportado; no diseñar operación continua en el máximo sin manual.
A9: Caudal publicado | B9: 7 | C9: L/min | D9: Dato publicado | E9: No se confirma que sea simultáneo con la presión nominal publicada.
A10: Temperatura máxima de agua reportada | B10: 50 | C10: °C | D10: Dato publicado | E10: La ficha de venta también marca «apto para agua caliente: No».
A11: Tensión eléctrica publicada | B11: 110 | C11: V | D11: Dato publicado | E11: Verificar placa y requisitos eléctricos de la instalación.
A12: Longitud de manguera incluida en venta | B12: 8 | C12: m | D12: Dato publicado | E12: No asumir que esta manguera sea la definida en arquitectura; el tramo de diseño indicado por el usuario es aprox. 4 m después del inyector.
A13: NPSHr | B13: 3 | C13: m | D13: Entrada requerida | E13: Solicitar al fabricante; para una hidrolavadora completa puede no publicarse como dato de usuario.
A14: Curva caudal-presión / manual oficial | B14: N/A | C14: URL / archivo | D14: Entrada requerida | E14: Registrar enlace o ruta al manual. No interpolar una curva no disponible.
A15: Potencia hidráulica indicativa a presión nominal | B15: =IF(OR(B7="",B9=""),"",B7*100000*B9/60000) -> 933.33333 | C15: W | D15: Calculado — solo screening | E15: Producto Q×Δp con valores publicados; no indica que ese punto exista en operación.
A16: Relación hidráulica/eléctrica indicativa | B16: =IF(OR(B15="",B6=""),"",B15/B6) -> 0.51851852 | C16: fracción | D16: No es eficiencia real | E16: No usar como eficiencia de bomba: Q y presión pueden corresponder a puntos distintos.

Sheet Venturi
A1: INYECTOR VENTURI Y DOSIFICACIÓN QUÍMICA
A2: No hay valores de fabricante suficientes en la página consultada para cerrar el modelo. Las pérdidas y la aspiración deben tomarse de curva/ficha técnica o ensayo.
A4: Parámetro | B4: Valor | C4: Unidad | D4: Tipo | E4: Fuente / observación
A5: Proveedor / familia | B5: Inyector chino | C5: — | D5: Referencia informada | E5: La página describe el principio Venturi; seleccionar una referencia y tamaño exactos.
A6: Modelo / tamaño exacto | B6: 3/4" | C6: — | D6: Entrada requerida | E6: Solicitar referencia, conexiones y ficha técnica.
A7: Presión de entrada de trabajo | B7: 3.11 | C7: bar(g) | D7: Entrada requerida | E7: Debe coincidir con caudal y contrapresión de operación.
A8: Caudal de agua operativo recomendado | B8: 7 | C8: L/min | D8: Entrada requerida | E8: Solicitar curva o tabla del fabricante.
A9: Contrapresión máxima / presión de salida | B9: 1.51 | C9: bar(g) | D9: Entrada requerida | E9: La aspiración depende de la presión de descarga además de la presión de entrada.
A10: Pérdida de presión a caudal de diseño | B10: 180 | C10: kPa | D10: Entrada requerida | E10: Dato esencial para el balance de presión de la red; obtener de fabricante o medir.
A11: Caudal de químico aspirado | B11: 0.1 | C11: L/min | D11: Entrada requerida | E11: Toca medirlo, pq no lo sabemos
A12: Caudal químico activo | B12: 0.1 | C12: L/min | D12: Calculado | E12: Solo vale si el modo seleccionado aspira producto.
A13: Caudal de mezcla a la salida | B13: =Datos_base!B22 -> 7 | C13: L/min | D13: Calculado | E13: Suma de agua y químico activo.
A14: Relación volumétrica agua / químico | B14: - | C14: — | D14: Medicion | E14: Q_agua / Q_químico; queda vacía cuando no se aspira químico.
A15: Fracción volumétrica de producto en mezcla | B15: =IF(OR(B12="",B13="",B13=0),"",B12/B13) -> 0.014285714 | C15: fracción | D15: Calculado | E15: Q_químico / (Q_agua + Q_químico). No equivale necesariamente a concentración activa del químico.
A16: Densidad del producto químico | B16: 1000 | C16: kg/m³ | D16: Entrada requerida | E16: Obtener de ficha del producto.
A17: Viscosidad dinámica del producto | B17: 0.001 | C17: Pa·s | D17: Entrada requerida | E17: Obtener de ficha del producto a temperatura de operación.
A18: Presión en garganta / puerto de aspiración | B18: -0.288 | C18: bar(g) | D18: Entrada requerida | E18: No inferirla solo con Bernoulli ideal sin geometría y coeficientes del inyector.
A19: Presión estimada a la entrada | B19: =IF(OR(Bomba!$B$7="",Tuberias!$B$36<>"GEOMETRÍA DECLARADA PARA TRAMOS ACTIVOS",Datos_base!$B$5="Pistola cerrada"),"",Bomba!$B$7-Tuberias!$B$32/100) -> 80 | C19: bar(g) | D19: Calculado | E19: Presión nominal de la hidrolavadora menos pérdidas calculadas antes del Venturi; solo referencia preliminar.
A20: Presión estimada a la salida | B20: =IF(OR(B19="",B10=""),"",B19-B10/100) -> 78.2 | C20: bar(g) | D20: Calculado | E20: Presión de entrada estimada menos la pérdida informada.
A22: Fuente: https://www.aqbasociados.com.co/producto/inyectores-quimicos-venturi/ — la información visible describe la función, pero no proporciona en el contenido consultado una curva cuantitativa para el modelo exacto.

Sheet Tuberias
A1: PÉRDIDAS DE CARGA EN TRAMOS FLEXIBLES Y ACCESORIOS
A2: Tabla genérica de hasta 20 tramos. Complete longitud, diámetro interno, rugosidad y K total. Los componentes con curva propia (filtro, calentador, Venturi, pistola y boquilla) se modelan aparte.
B4: Conversión a pulgadas | C4: =3/4 -> 0.75 | D4: =C4*25.4 -> 19.05 | E4: mm
A7: ID | B7: Circuito | C7: Tramo | D7: Desde | E7: Hasta | F7: Fluido | G7: Longitud L (m) | H7: Di interno (mm) | I7: Rugosidad ε (mm) | J7: ΣK | K7: Caudal Q (L/min) | L7: Densidad (kg/m³) | M7: Viscosidad μ (Pa·s) | N7: Área (m²) | O7: Velocidad (m/s) | P7: Reynolds | Q7: ε/Di | R7: f Darcy | S7: hf (m) | T7: hK (m) | U7: ΔP (kPa) | V7: Geometría del tramo
A8: T-01 | B8: Succión | C8: Acometida a filtro | D8: Punto de agua | E8: Filtro | F8: Agua | G8: 1 | H8: =$D$4 -> 19.05 | I8: 0.0015 | J8: 0 | K8: =IF(OR($B8="",$F8=""),"",IF(Datos_base!$B$5="Pistola cerrada",0,IF($F8="Agua",Datos_base!$B$20,IF($F8="Mezcla",Datos_base!$B$22,IF($F8="Químico",Datos_base!$B$21,""))))) -> 7 | L8: =IF(OR($B8="",$F8=""),"",IF($F8="Químico",IF(OR(Datos_base!$B$21="",Datos_base!$B$21=0,Venturi!$B$16=""),"",Venturi!$B$16),Propiedades!$B$12)) -> 992.24732 | M8: =IF(OR($B8="",$F8=""),"",IF($F8="Químico",IF(OR(Datos_base!$B$21="",Datos_base!$B$21=0,Venturi!$B$17=""),"",Venturi!$B$17),Propiedades!$B$13)) -> 0.00065142788 | N8: =IF(OR(H8="",H8<=0),"",PI()*(H8/1000)^2/4) -> 0.00028502296 | O8: =IF(OR(K8="",N8="",N8=0),"",K8/60000/N8) -> 0.40932375 | P8: =IF(OR(L8="",O8="",H8="",M8="",M8=0),"",L8*O8*(H8/1000)/M8) -> 11877.24 | Q8: =IF(OR(I8="",H8="",H8=0),"",I8/H8) -> 7.8740157e-05 | R8: =IF(OR(P8="",P8<=0,H8="",H8<=0,I8=""),"",IF(P8<2300,64/P8,0.25/(LOG10(I8/(3.7*H8)+5.74/(P8^0.9))^2))) -> 0.029707824 | S8: =IF(OR(G8="",H8="",H8<=0,R8="",O8=""),"",R8*(G8/(H8/1000))*O8^2/(2*Datos_base!$B$6)) -> 0.013317133 | T8: =IF(OR(J8="",O8=""),"",J8*O8^2/(2*Datos_base!$B$6)) -> 0 | U8: =IF(OR(L8="",O8="",S8="",T8=""),"",L8*Datos_base!$B$6*(S8+T8)/1000) -> 0.12962826 | V8: =IF(OR($B8="",$C8=""),"",IF(AND($G8<>"",$H8<>"",$I8<>""),"OK","INCOMPLETO")) -> OK
A9: T-02 | B9: Succión | C9: Filtro a calentador | D9: Filtro | E9: Calentador | F9: Agua | G9: 1 | H9: =$D$4 -> 19.05 | I9: 0.0015 | J9: 0 | K9: =IF(OR($B9="",$F9=""),"",IF(Datos_base!$B$5="Pistola cerrada",0,IF($F9="Agua",Datos_base!$B$20,IF($F9="Mezcla",Datos_base!$B$22,IF($F9="Químico",Datos_base!$B$21,""))))) -> 7 | L9: =IF(OR($B9="",$F9=""),"",IF($F9="Químico",IF(OR(Datos_base!$B$21="",Datos_base!$B$21=0,Venturi!$B$16=""),"",Venturi!$B$16),Propiedades!$B$12)) -> 992.24732 | M9: =IF(OR($B9="",$F9=""),"",IF($F9="Químico",IF(OR(Datos_base!$B$21="",Datos_base!$B$21=0,Venturi!$B$17=""),"",Venturi!$B$17),Propiedades!$B$13)) -> 0.00065142788 | N9: =IF(OR(H9="",H9<=0),"",PI()*(H9/1000)^2/4) -> 0.00028502296 | O9: =IF(OR(K9="",N9="",N9=0),"",K9/60000/N9) -> 0.40932375 | P9: =IF(OR(L9="",O9="",H9="",M9="",M9=0),"",L9*O9*(H9/1000)/M9) -> 11877.24 | Q9: =IF(OR(I9="",H9="",H9=0),"",I9/H9) -> 7.8740157e-05 | R9: =IF(OR(P9="",P9<=0,H9="",H9<=0,I9=""),"",IF(P9<2300,64/P9,0.25/(LOG10(I9/(3.7*H9)+5.74/(P9^0.9))^2))) -> 0.029707824 | S9: =IF(OR(G9="",H9="",H9<=0,R9="",O9=""),"",R9*(G9/(H9/1000))*O9^2/(2*Datos_base!$B$6)) -> 0.013317133 | T9: =IF(OR(J9="",O9=""),"",J9*O9^2/(2*Datos_base!$B$6)) -> 0 | U9: =IF(OR(L9="",O9="",S9="",T9=""),"",L9*Datos_base!$B$6*(S9+T9)/1000) -> 0.12962826 | V9: =IF(OR($B9="",$C9=""),"",IF(AND($G9<>"",$H9<>"",$I9<>""),"OK","INCOMPLETO")) -> OK
A10: T-03 | B10: Succión | C10: Calentador a succión de bomba | D10: Calentador | E10: Bomba | F10: Agua | G10: 1 | H10: =$D$4 -> 19.05 | I10: 0.0015 | J10: 0 | K10: =IF(OR($B10="",$F10=""),"",IF(Datos_base!$B$5="Pistola cerrada",0,IF($F10="Agua",Datos_base!$B$20,IF($F10="Mezcla",Datos_base!$B$22,IF($F10="Químico",Datos_base!$B$21,""))))) -> 7 | L10: =IF(OR($B10="",$F10=""),"",IF($F10="Químico",IF(OR(Datos_base!$B$21="",Datos_base!$B$21=0,Venturi!$B$16=""),"",Venturi!$B$16),Propiedades!$B$12)) -> 992.24732 | M10: =IF(OR($B10="",$F10=""),"",IF($F10="Químico",IF(OR(Datos_base!$B$21="",Datos_base!$B$21=0,Venturi!$B$17=""),"",Venturi!$B$17),Propiedades!$B$13)) -> 0.00065142788 | N10: =IF(OR(H10="",H10<=0),"",PI()*(H10/1000)^2/4) -> 0.00028502296 | O10: =IF(OR(K10="",N10="",N10=0),"",K10/60000/N10) -> 0.40932375 | P10: =IF(OR(L10="",O10="",H10="",M10="",M10=0),"",L10*O10*(H10/1000)/M10) -> 11877.24 | Q10: =IF(OR(I10="",H10="",H10=0),"",I10/H10) -> 7.8740157e-05 | R10: =IF(OR(P10="",P10<=0,H10="",H10<=0,I10=""),"",IF(P10<2300,64/P10,0.25/(LOG10(I10/(3.7*H10)+5.74/(P10^0.9))^2))) -> 0.029707824 | S10: =IF(OR(G10="",H10="",H10<=0,R10="",O10=""),"",R10*(G10/(H10/1000))*O10^2/(2*Datos_base!$B$6)) -> 0.013317133 | T10: =IF(OR(J10="",O10=""),"",J10*O10^2/(2*Datos_base!$B$6)) -> 0 | U10: =IF(OR(L10="",O10="",S10="",T10=""),"",L10*Datos_base!$B$6*(S10+T10)/1000) -> 0.12962826 | V10: =IF(OR($B10="",$C10=""),"",IF(AND($G10<>"",$H10<>"",$I10<>""),"OK","INCOMPLETO")) -> OK
A11: T-04 | B11: Antes Venturi | C11: Descarga bomba a entrada Venturi | D11: Bomba | E11: Venturi | F11: Agua | G11: 0 | H11: =$D$4 -> 19.05 | I11: 0.0015 | J11: 0 | K11: =IF(OR($B11="",$F11=""),"",IF(Datos_base!$B$5="Pistola cerrada",0,IF($F11="Agua",Datos_base!$B$20,IF($F11="Mezcla",Datos_base!$B$22,IF($F11="Químico",Datos_base!$B$21,""))))) -> 7 | L11: =IF(OR($B11="",$F11=""),"",IF($F11="Químico",IF(OR(Datos_base!$B$21="",Datos_base!$B$21=0,Venturi!$B$16=""),"",Venturi!$B$16),Propiedades!$B$12)) -> 992.24732 | M11: =IF(OR($B11="",$F11=""),"",IF($F11="Químico",IF(OR(Datos_base!$B$21="",Datos_base!$B$21=0,Venturi!$B$17=""),"",Venturi!$B$17),Propiedades!$B$13)) -> 0.00065142788 | N11: =IF(OR(H11="",H11<=0),"",PI()*(H11/1000)^2/4) -> 0.00028502296 | O11: =IF(OR(K11="",N11="",N11=0),"",K11/60000/N11) -> 0.40932375 | P11: =IF(OR(L11="",O11="",H11="",M11="",M11=0),"",L11*O11*(H11/1000)/M11) -> 11877.24 | Q11: =IF(OR(I11="",H11="",H11=0),"",I11/H11) -> 7.8740157e-05 | R11: =IF(OR(P11="",P11<=0,H11="",H11<=0,I11=""),"",IF(P11<2300,64/P11,0.25/(LOG10(I11/(3.7*H11)+5.74/(P11^0.9))^2))) -> 0.029707824 | S11: =IF(OR(G11="",H11="",H11<=0,R11="",O11=""),"",R11*(G11/(H11/1000))*O11^2/(2*Datos_base!$B$6)) -> 0 | T11: =IF(OR(J11="",O11=""),"",J11*O11^2/(2*Datos_base!$B$6)) -> 0 | U11: =IF(OR(L11="",O11="",S11="",T11=""),"",L11*Datos_base!$B$6*(S11+T11)/1000) -> 0 | V11: =IF(OR($B11="",$C11=""),"",IF(AND($G11<>"",$H11<>"",$I11<>""),"OK","INCOMPLETO")) -> OK
A12: T-05 | B12: Después Venturi | C12: Salida Venturi a pistola (tramo principal) | D12: Venturi | E12: Pistola | F12: Mezcla | G12: =Bomba!$B$12 -> 8 | H12: =$D$4 -> 19.05 | I12: 0.0015 | J12: 0 | K12: =IF(OR($B12="",$F12=""),"",IF(Datos_base!$B$5="Pistola cerrada",0,IF($F12="Agua",Datos_base!$B$20,IF($F12="Mezcla",Datos_base!$B$22,IF($F12="Químico",Datos_base!$B$21,""))))) -> 7 | L12: =IF(OR($B12="",$F12=""),"",IF($F12="Químico",IF(OR(Datos_base!$B$21="",Datos_base!$B$21=0,Venturi!$B$16=""),"",Venturi!$B$16),Propiedades!$B$12)) -> 992.24732 | M12: =IF(OR($B12="",$F12=""),"",IF($F12="Químico",IF(OR(Datos_base!$B$21="",Datos_base!$B$21=0,Venturi!$B$17=""),"",Venturi!$B$17),Propiedades!$B$13)) -> 0.00065142788 | N12: =IF(OR(H12="",H12<=0),"",PI()*(H12/1000)^2/4) -> 0.00028502296 | O12: =IF(OR(K12="",N12="",N12=0),"",K12/60000/N12) -> 0.40932375 | P12: =IF(OR(L12="",O12="",H12="",M12="",M12=0),"",L12*O12*(H12/1000)/M12) -> 11877.24 | Q12: =IF(OR(I12="",H12="",H12=0),"",I12/H12) -> 7.8740157e-05 | R12: =IF(OR(P12="",P12<=0,H12="",H12<=0,I12=""),"",IF(P12<2300,64/P12,0.25/(LOG10(I12/(3.7*H12)+5.74/(P12^0.9))^2))) -> 0.029707824 | S12: =IF(OR(G12="",H12="",H12<=0,R12="",O12=""),"",R12*(G12/(H12/1000))*O12^2/(2*Datos_base!$B$6)) -> 0.10653707 | T12: =IF(OR(J12="",O12=""),"",J12*O12^2/(2*Datos_base!$B$6)) -> 0 | U12: =IF(OR(L12="",O12="",S12="",T12=""),"",L12*Datos_base!$B$6*(S12+T12)/1000) -> 1.0370261 | V12: =IF(OR($B12="",$C12=""),"",IF(AND($G12<>"",$H12<>"",$I12<>""),"OK","INCOMPLETO")) -> OK
A13: T-06 | B13: Después Venturi | C13: Pistola a boquilla / lanza | D13: Pistola | E13: Boquilla | F13: Mezcla | G13: 0.3 | H13: =$D$4 -> 19.05 | I13: 0.0015 | J13: 0 | K13: =IF(OR($B13="",$F13=""),"",IF(Datos_base!$B$5="Pistola cerrada",0,IF($F13="Agua",Datos_base!$B$20,IF($F13="Mezcla",Datos_base!$B$22,IF($F13="Químico",Datos_base!$B$21,""))))) -> 7 | L13: =IF(OR($B13="",$F13=""),"",IF($F13="Químico",IF(OR(Datos_base!$B$21="",Datos_base!$B$21=0,Venturi!$B$16=""),"",Venturi!$B$16),Propiedades!$B$12)) -> 992.24732 | M13: =IF(OR($B13="",$F13=""),"",IF($F13="Químico",IF(OR(Datos_base!$B$21="",Datos_base!$B$21=0,Venturi!$B$17=""),"",Venturi!$B$17),Propiedades!$B$13)) -> 0.00065142788 | N13: =IF(OR(H13="",H13<=0),"",PI()*(H13/1000)^2/4) -> 0.00028502296 | O13: =IF(OR(K13="",N13="",N13=0),"",K13/60000/N13) -> 0.40932375 | P13: =IF(OR(L13="",O13="",H13="",M13="",M13=0),"",L13*O13*(H13/1000)/M13) -> 11877.24 | Q13: =IF(OR(I13="",H13="",H13=0),"",I13/H13) -> 7.8740157e-05 | R13: =IF(OR(P13="",P13<=0,H13="",H13<=0,I13=""),"",IF(P13<2300,64/P13,0.25/(LOG10(I13/(3.7*H13)+5.74/(P13^0.9))^2))) -> 0.029707824 | S13: =IF(OR(G13="",H13="",H13<=0,R13="",O13=""),"",R13*(G13/(H13/1000))*O13^2/(2*Datos_base!$B$6)) -> 0.00399514 | T13: =IF(OR(J13="",O13=""),"",J13*O13^2/(2*Datos_base!$B$6)) -> 0 | U13: =IF(OR(L13="",O13="",S13="",T13=""),"",L13*Datos_base!$B$6*(S13+T13)/1000) -> 0.038888478 | V13: =IF(OR($B13="",$C13=""),"",IF(AND($G13<>"",$H13<>"",$I13<>""),"OK","INCOMPLETO")) -> OK
A14: T-07 | B14: Químicos | C14: Depósito químico a puerto de aspiración | D14: Depósito | E14: Venturi | F14: Químico | G14: 2 | H14: 10 | I14: 0.0015 | J14: 0 | K14: =IF(OR($B14="",$F14=""),"",IF(Datos_base!$B$5="Pistola cerrada",0,IF($F14="Agua",Datos_base!$B$20,IF($F14="Mezcla",Datos_base!$B$22,IF($F14="Químico",Datos_base!$B$21,""))))) -> 0 | L14: =IF(OR($B14="",$F14=""),"",IF($F14="Químico",IF(OR(Datos_base!$B$21="",Datos_base!$B$21=0,Venturi!$B$16=""),"",Venturi!$B$16),Propiedades!$B$12)) | M14: =IF(OR($B14="",$F14=""),"",IF($F14="Químico",IF(OR(Datos_base!$B$21="",Datos_base!$B$21=0,Venturi!$B$17=""),"",Venturi!$B$17),Propiedades!$B$13)) | N14: =IF(OR(H14="",H14<=0),"",PI()*(H14/1000)^2/4) -> 7.8539816e-05 | O14: =IF(OR(K14="",N14="",N14=0),"",K14/60000/N14) -> 0 | P14: =IF(OR(L14="",O14="",H14="",M14="",M14=0),"",L14*O14*(H14/1000)/M14) | Q14: =IF(OR(I14="",H14="",H14=0),"",I14/H14) -> 0.00015 | R14: =IF(OR(P14="",P14<=0,H14="",H14<=0,I14=""),"",IF(P14<2300,64/P14,0.25/(LOG10(I14/(3.7*H14)+5.74/(P14^0.9))^2))) | S14: =IF(OR(G14="",H14="",H14<=0,R14="",O14=""),"",R14*(G14/(H14/1000))*O14^2/(2*Datos_base!$B$6)) | T14: =IF(OR(J14="",O14=""),"",J14*O14^2/(2*Datos_base!$B$6)) -> 0 | U14: =IF(OR(L14="",O14="",S14="",T14=""),"",L14*Datos_base!$B$6*(S14+T14)/1000) | V14: =IF(OR($B14="",$C14=""),"",IF(AND($G14<>"",$H14<>"",$I14<>""),"OK","INCOMPLETO")) -> OK
A15: T-08 | C15: Tramo adicional 01 | J15: 0 | K15: =IF(OR($B15="",$F15=""),"",IF(Datos_base!$B$5="Pistola cerrada",0,IF($F15="Agua",Datos_base!$B$20,IF($F15="Mezcla",Datos_base!$B$22,IF($F15="Químico",Datos_base!$B$21,""))))) | L15: =IF(OR($B15="",$F15=""),"",IF($F15="Químico",IF(OR(Datos_base!$B$21="",Datos_base!$B$21=0,Venturi!$B$16=""),"",Venturi!$B$16),Propiedades!$B$12)) | M15: =IF(OR($B15="",$F15=""),"",IF($F15="Químico",IF(OR(Datos_base!$B$21="",Datos_base!$B$21=0,Venturi!$B$17=""),"",Venturi!$B$17),Propiedades!$B$13)) | N15: =IF(OR(H15="",H15<=0),"",PI()*(H15/1000)^2/4) | O15: =IF(OR(K15="",N15="",N15=0),"",K15/60000/N15) | P15: =IF(OR(L15="",O15="",H15="",M15="",M15=0),"",L15*O15*(H15/1000)/M15) | Q15: =IF(OR(I15="",H15="",H15=0),"",I15/H15) | R15: =IF(OR(P15="",P15<=0,H15="",H15<=0,I15=""),"",IF(P15<2300,64/P15,0.25/(LOG10(I15/(3.7*H15)+5.74/(P15^0.9))^2))) | S15: =IF(OR(G15="",H15="",H15<=0,R15="",O15=""),"",R15*(G15/(H15/1000))*O15^2/(2*Datos_base!$B$6)) | T15: =IF(OR(J15="",O15=""),"",J15*O15^2/(2*Datos_base!$B$6)) | U15: =IF(OR(L15="",O15="",S15="",T15=""),"",L15*Datos_base!$B$6*(S15+T15)/1000) | V15: =IF(OR($B15="",$C15=""),"",IF(AND($G15<>"",$H15<>"",$I15<>""),"OK","INCOMPLETO"))
A16: T-09 | C16: Tramo adicional 02 | J16: 0 | K16: =IF(OR($B16="",$F16=""),"",IF(Datos_base!$B$5="Pistola cerrada",0,IF($F16="Agua",Datos_base!$B$20,IF($F16="Mezcla",Datos_base!$B$22,IF($F16="Químico",Datos_base!$B$21,""))))) | L16: =IF(OR($B16="",$F16=""),"",IF($F16="Químico",IF(OR(Datos_base!$B$21="",Datos_base!$B$21=0,Venturi!$B$16=""),"",Venturi!$B$16),Propiedades!$B$12)) | M16: =IF(OR($B16="",$F16=""),"",IF($F16="Químico",IF(OR(Datos_base!$B$21="",Datos_base!$B$21=0,Venturi!$B$17=""),"",Venturi!$B$17),Propiedades!$B$13)) | N16: =IF(OR(H16="",H16<=0),"",PI()*(H16/1000)^2/4) | O16: =IF(OR(K16="",N16="",N16=0),"",K16/60000/N16) | P16: =IF(OR(L16="",O16="",H16="",M16="",M16=0),"",L16*O16*(H16/1000)/M16) | Q16: =IF(OR(I16="",H16="",H16=0),"",I16/H16) | R16: =IF(OR(P16="",P16<=0,H16="",H16<=0,I16=""),"",IF(P16<2300,64/P16,0.25/(LOG10(I16/(3.7*H16)+5.74/(P16^0.9))^2))) | S16: =IF(OR(G16="",H16="",H16<=0,R16="",O16=""),"",R16*(G16/(H16/1000))*O16^2/(2*Datos_base!$B$6)) | T16: =IF(OR(J16="",O16=""),"",J16*O16^2/(2*Datos_base!$B$6)) | U16: =IF(OR(L16="",O16="",S16="",T16=""),"",L16*Datos_base!$B$6*(S16+T16)/1000) | V16: =IF(OR($B16="",$C16=""),"",IF(AND($G16<>"",$H16<>"",$I16<>""),"OK","INCOMPLETO"))
A17: T-10 | C17: Tramo adicional 03 | J17: 0 | K17: =IF(OR($B17="",$F17=""),"",IF(Datos_base!$B$5="Pistola cerrada",0,IF($F17="Agua",Datos_base!$B$20,IF($F17="Mezcla",Datos_base!$B$22,IF($F17="Químico",Datos_base!$B$21,""))))) | L17: =IF(OR($B17="",$F17=""),"",IF($F17="Químico",IF(OR(Datos_base!$B$21="",Datos_base!$B$21=0,Venturi!$B$16=""),"",Venturi!$B$16),Propiedades!$B$12)) | M17: =IF(OR($B17="",$F17=""),"",IF($F17="Químico",IF(OR(Datos_base!$B$21="",Datos_base!$B$21=0,Venturi!$B$17=""),"",Venturi!$B$17),Propiedades!$B$13)) | N17: =IF(OR(H17="",H17<=0),"",PI()*(H17/1000)^2/4) | O17: =IF(OR(K17="",N17="",N17=0),"",K17/60000/N17) | P17: =IF(OR(L17="",O17="",H17="",M17="",M17=0),"",L17*O17*(H17/1000)/M17) | Q17: =IF(OR(I17="",H17="",H17=0),"",I17/H17) | R17: =IF(OR(P17="",P17<=0,H17="",H17<=0,I17=""),"",IF(P17<2300,64/P17,0.25/(LOG10(I17/(3.7*H17)+5.74/(P17^0.9))^2))) | S17: =IF(OR(G17="",H17="",H17<=0,R17="",O17=""),"",R17*(G17/(H17/1000))*O17^2/(2*Datos_base!$B$6)) | T17: =IF(OR(J17="",O17=""),"",J17*O17^2/(2*Datos_base!$B$6)) | U17: =IF(OR(L17="",O17="",S17="",T17=""),"",L17*Datos_base!$B$6*(S17+T17)/1000) | V17: =IF(OR($B17="",$C17=""),"",IF(AND($G17<>"",$H17<>"",$I17<>""),"OK","INCOMPLETO"))
A18: T-11 | C18: Tramo adicional 04 | J18: 0 | K18: =IF(OR($B18="",$F18=""),"",IF(Datos_base!$B$5="Pistola cerrada",0,IF($F18="Agua",Datos_base!$B$20,IF($F18="Mezcla",Datos_base!$B$22,IF($F18="Químico",Datos_base!$B$21,""))))) | L18: =IF(OR($B18="",$F18=""),"",IF($F18="Químico",IF(OR(Datos_base!$B$21="",Datos_base!$B$21=0,Venturi!$B$16=""),"",Venturi!$B$16),Propiedades!$B$12)) | M18: =IF(OR($B18="",$F18=""),"",IF($F18="Químico",IF(OR(Datos_base!$B$21="",Datos_base!$B$21=0,Venturi!$B$17=""),"",Venturi!$B$17),Propiedades!$B$13)) | N18: =IF(OR(H18="",H18<=0),"",PI()*(H18/1000)^2/4) | O18: =IF(OR(K18="",N18="",N18=0),"",K18/60000/N18) | P18: =IF(OR(L18="",O18="",H18="",M18="",M18=0),"",L18*O18*(H18/1000)/M18) | Q18: =IF(OR(I18="",H18="",H18=0),"",I18/H18) | R18: =IF(OR(P18="",P18<=0,H18="",H18<=0,I18=""),"",IF(P18<2300,64/P18,0.25/(LOG10(I18/(3.7*H18)+5.74/(P18^0.9))^2))) | S18: =IF(OR(G18="",H18="",H18<=0,R18="",O18=""),"",R18*(G18/(H18/1000))*O18^2/(2*Datos_base!$B$6)) | T18: =IF(OR(J18="",O18=""),"",J18*O18^2/(2*Datos_base!$B$6)) | U18: =IF(OR(L18="",O18="",S18="",T18=""),"",L18*Datos_base!$B$6*(S18+T18)/1000) | V18: =IF(OR($B18="",$C18=""),"",IF(AND($G18<>"",$H18<>"",$I18<>""),"OK","INCOMPLETO"))
A19: T-12 | C19: Tramo adicional 05 | J19: 0 | K19: =IF(OR($B19="",$F19=""),"",IF(Datos_base!$B$5="Pistola cerrada",0,IF($F19="Agua",Datos_base!$B$20,IF($F19="Mezcla",Datos_base!$B$22,IF($F19="Químico",Datos_base!$B$21,""))))) | L19: =IF(OR($B19="",$F19=""),"",IF($F19="Químico",IF(OR(Datos_base!$B$21="",Datos_base!$B$21=0,Venturi!$B$16=""),"",Venturi!$B$16),Propiedades!$B$12)) | M19: =IF(OR($B19="",$F19=""),"",IF($F19="Químico",IF(OR(Datos_base!$B$21="",Datos_base!$B$21=0,Venturi!$B$17=""),"",Venturi!$B$17),Propiedades!$B$13)) | N19: =IF(OR(H19="",H19<=0),"",PI()*(H19/1000)^2/4) | O19: =IF(OR(K19="",N19="",N19=0),"",K19/60000/N19) | P19: =IF(OR(L19="",O19="",H19="",M19="",M19=0),"",L19*O19*(H19/1000)/M19) | Q19: =IF(OR(I19="",H19="",H19=0),"",I19/H19) | R19: =IF(OR(P19="",P19<=0,H19="",H19<=0,I19=""),"",IF(P19<2300,64/P19,0.25/(LOG10(I19/(3.7*H19)+5.74/(P19^0.9))^2))) | S19: =IF(OR(G19="",H19="",H19<=0,R19="",O19=""),"",R19*(G19/(H19/1000))*O19^2/(2*Datos_base!$B$6)) | T19: =IF(OR(J19="",O19=""),"",J19*O19^2/(2*Datos_base!$B$6)) | U19: =IF(OR(L19="",O19="",S19="",T19=""),"",L19*Datos_base!$B$6*(S19+T19)/1000) | V19: =IF(OR($B19="",$C19=""),"",IF(AND($G19<>"",$H19<>"",$I19<>""),"OK","INCOMPLETO"))
A20: T-13 | C20: Tramo adicional 06 | J20: 0 | K20: =IF(OR($B20="",$F20=""),"",IF(Datos_base!$B$5="Pistola cerrada",0,IF($F20="Agua",Datos_base!$B$20,IF($F20="Mezcla",Datos_base!$B$22,IF($F20="Químico",Datos_base!$B$21,""))))) | L20: =IF(OR($B20="",$F20=""),"",IF($F20="Químico",IF(OR(Datos_base!$B$21="",Datos_base!$B$21=0,Venturi!$B$16=""),"",Venturi!$B$16),Propiedades!$B$12)) | M20: =IF(OR($B20="",$F20=""),"",IF($F20="Químico",IF(OR(Datos_base!$B$21="",Datos_base!$B$21=0,Venturi!$B$17=""),"",Venturi!$B$17),Propiedades!$B$13)) | N20: =IF(OR(H20="",H20<=0),"",PI()*(H20/1000)^2/4) | O20: =IF(OR(K20="",N20="",N20=0),"",K20/60000/N20) | P20: =IF(OR(L20="",O20="",H20="",M20="",M20=0),"",L20*O20*(H20/1000)/M20) | Q20: =IF(OR(I20="",H20="",H20=0),"",I20/H20) | R20: =IF(OR(P20="",P20<=0,H20="",H20<=0,I20=""),"",IF(P20<2300,64/P20,0.25/(LOG10(I20/(3.7*H20)+5.74/(P20^0.9))^2))) | S20: =IF(OR(G20="",H20="",H20<=0,R20="",O20=""),"",R20*(G20/(H20/1000))*O20^2/(2*Datos_base!$B$6)) | T20: =IF(OR(J20="",O20=""),"",J20*O20^2/(2*Datos_base!$B$6)) | U20: =IF(OR(L20="",O20="",S20="",T20=""),"",L20*Datos_base!$B$6*(S20+T20)/1000) | V20: =IF(OR($B20="",$C20=""),"",IF(AND($G20<>"",$H20<>"",$I20<>""),"OK","INCOMPLETO"))
A21: T-14 | C21: Tramo adicional 07 | J21: 0 | K21: =IF(OR($B21="",$F21=""),"",IF(Datos_base!$B$5="Pistola cerrada",0,IF($F21="Agua",Datos_base!$B$20,IF($F21="Mezcla",Datos_base!$B$22,IF($F21="Químico",Datos_base!$B$21,""))))) | L21: =IF(OR($B21="",$F21=""),"",IF($F21="Químico",IF(OR(Datos_base!$B$21="",Datos_base!$B$21=0,Venturi!$B$16=""),"",Venturi!$B$16),Propiedades!$B$12)) | M21: =IF(OR($B21="",$F21=""),"",IF($F21="Químico",IF(OR(Datos_base!$B$21="",Datos_base!$B$21=0,Venturi!$B$17=""),"",Venturi!$B$17),Propiedades!$B$13)) | N21: =IF(OR(H21="",H21<=0),"",PI()*(H21/1000)^2/4) | O21: =IF(OR(K21="",N21="",N21=0),"",K21/60000/N21) | P21: =IF(OR(L21="",O21="",H21="",M21="",M21=0),"",L21*O21*(H21/1000)/M21) | Q21: =IF(OR(I21="",H21="",H21=0),"",I21/H21) | R21: =IF(OR(P21="",P21<=0,H21="",H21<=0,I21=""),"",IF(P21<2300,64/P21,0.25/(LOG10(I21/(3.7*H21)+5.74/(P21^0.9))^2))) | S21: =IF(OR(G21="",H21="",H21<=0,R21="",O21=""),"",R21*(G21/(H21/1000))*O21^2/(2*Datos_base!$B$6)) | T21: =IF(OR(J21="",O21=""),"",J21*O21^2/(2*Datos_base!$B$6)) | U21: =IF(OR(L21="",O21="",S21="",T21=""),"",L21*Datos_base!$B$6*(S21+T21)/1000) | V21: =IF(OR($B21="",$C21=""),"",IF(AND($G21<>"",$H21<>"",$I21<>""),"OK","INCOMPLETO"))
A22: T-15 | C22: Tramo adicional 08 | J22: 0 | K22: =IF(OR($B22="",$F22=""),"",IF(Datos_base!$B$5="Pistola cerrada",0,IF($F22="Agua",Datos_base!$B$20,IF($F22="Mezcla",Datos_base!$B$22,IF($F22="Químico",Datos_base!$B$21,""))))) | L22: =IF(OR($B22="",$F22=""),"",IF($F22="Químico",IF(OR(Datos_base!$B$21="",Datos_base!$B$21=0,Venturi!$B$16=""),"",Venturi!$B$16),Propiedades!$B$12)) | M22: =IF(OR($B22="",$F22=""),"",IF($F22="Químico",IF(OR(Datos_base!$B$21="",Datos_base!$B$21=0,Venturi!$B$17=""),"",Venturi!$B$17),Propiedades!$B$13)) | N22: =IF(OR(H22="",H22<=0),"",PI()*(H22/1000)^2/4) | O22: =IF(OR(K22="",N22="",N22=0),"",K22/60000/N22) | P22: =IF(OR(L22="",O22="",H22="",M22="",M22=0),"",L22*O22*(H22/1000)/M22) | Q22: =IF(OR(I22="",H22="",H22=0),"",I22/H22) | R22: =IF(OR(P22="",P22<=0,H22="",H22<=0,I22=""),"",IF(P22<2300,64/P22,0.25/(LOG10(I22/(3.7*H22)+5.74/(P22^0.9))^2))) | S22: =IF(OR(G22="",H22="",H22<=0,R22="",O22=""),"",R22*(G22/(H22/1000))*O22^2/(2*Datos_base!$B$6)) | T22: =IF(OR(J22="",O22=""),"",J22*O22^2/(2*Datos_base!$B$6)) | U22: =IF(OR(L22="",O22="",S22="",T22=""),"",L22*Datos_base!$B$6*(S22+T22)/1000) | V22: =IF(OR($B22="",$C22=""),"",IF(AND($G22<>"",$H22<>"",$I22<>""),"OK","INCOMPLETO"))
A23: T-16 | C23: Tramo adicional 09 | J23: 0 | K23: =IF(OR($B23="",$F23=""),"",IF(Datos_base!$B$5="Pistola cerrada",0,IF($F23="Agua",Datos_base!$B$20,IF($F23="Mezcla",Datos_base!$B$22,IF($F23="Químico",Datos_base!$B$21,""))))) | L23: =IF(OR($B23="",$F23=""),"",IF($F23="Químico",IF(OR(Datos_base!$B$21="",Datos_base!$B$21=0,Venturi!$B$16=""),"",Venturi!$B$16),Propiedades!$B$12)) | M23: =IF(OR($B23="",$F23=""),"",IF($F23="Químico",IF(OR(Datos_base!$B$21="",Datos_base!$B$21=0,Venturi!$B$17=""),"",Venturi!$B$17),Propiedades!$B$13)) | N23: =IF(OR(H23="",H23<=0),"",PI()*(H23/1000)^2/4) | O23: =IF(OR(K23="",N23="",N23=0),"",K23/60000/N23) | P23: =IF(OR(L23="",O23="",H23="",M23="",M23=0),"",L23*O23*(H23/1000)/M23) | Q23: =IF(OR(I23="",H23="",H23=0),"",I23/H23) | R23: =IF(OR(P23="",P23<=0,H23="",H23<=0,I23=""),"",IF(P23<2300,64/P23,0.25/(LOG10(I23/(3.7*H23)+5.74/(P23^0.9))^2))) | S23: =IF(OR(G23="",H23="",H23<=0,R23="",O23=""),"",R23*(G23/(H23/1000))*O23^2/(2*Datos_base!$B$6)) | T23: =IF(OR(J23="",O23=""),"",J23*O23^2/(2*Datos_base!$B$6)) | U23: =IF(OR(L23="",O23="",S23="",T23=""),"",L23*Datos_base!$B$6*(S23+T23)/1000) | V23: =IF(OR($B23="",$C23=""),"",IF(AND($G23<>"",$H23<>"",$I23<>""),"OK","INCOMPLETO"))
A24: T-17 | C24: Tramo adicional 10 | J24: 0 | K24: =IF(OR($B24="",$F24=""),"",IF(Datos_base!$B$5="Pistola cerrada",0,IF($F24="Agua",Datos_base!$B$20,IF($F24="Mezcla",Datos_base!$B$22,IF($F24="Químico",Datos_base!$B$21,""))))) | L24: =IF(OR($B24="",$F24=""),"",IF($F24="Químico",IF(OR(Datos_base!$B$21="",Datos_base!$B$21=0,Venturi!$B$16=""),"",Venturi!$B$16),Propiedades!$B$12)) | M24: =IF(OR($B24="",$F24=""),"",IF($F24="Químico",IF(OR(Datos_base!$B$21="",Datos_base!$B$21=0,Venturi!$B$17=""),"",Venturi!$B$17),Propiedades!$B$13)) | N24: =IF(OR(H24="",H24<=0),"",PI()*(H24/1000)^2/4) | O24: =IF(OR(K24="",N24="",N24=0),"",K24/60000/N24) | P24: =IF(OR(L24="",O24="",H24="",M24="",M24=0),"",L24*O24*(H24/1000)/M24) | Q24: =IF(OR(I24="",H24="",H24=0),"",I24/H24) | R24: =IF(OR(P24="",P24<=0,H24="",H24<=0,I24=""),"",IF(P24<2300,64/P24,0.25/(LOG10(I24/(3.7*H24)+5.74/(P24^0.9))^2))) | S24: =IF(OR(G24="",H24="",H24<=0,R24="",O24=""),"",R24*(G24/(H24/1000))*O24^2/(2*Datos_base!$B$6)) | T24: =IF(OR(J24="",O24=""),"",J24*O24^2/(2*Datos_base!$B$6)) | U24: =IF(OR(L24="",O24="",S24="",T24=""),"",L24*Datos_base!$B$6*(S24+T24)/1000) | V24: =IF(OR($B24="",$C24=""),"",IF(AND($G24<>"",$H24<>"",$I24<>""),"OK","INCOMPLETO"))
A25: T-18 | C25: Tramo adicional 11 | J25: 0 | K25: =IF(OR($B25="",$F25=""),"",IF(Datos_base!$B$5="Pistola cerrada",0,IF($F25="Agua",Datos_base!$B$20,IF($F25="Mezcla",Datos_base!$B$22,IF($F25="Químico",Datos_base!$B$21,""))))) | L25: =IF(OR($B25="",$F25=""),"",IF($F25="Químico",IF(OR(Datos_base!$B$21="",Datos_base!$B$21=0,Venturi!$B$16=""),"",Venturi!$B$16),Propiedades!$B$12)) | M25: =IF(OR($B25="",$F25=""),"",IF($F25="Químico",IF(OR(Datos_base!$B$21="",Datos_base!$B$21=0,Venturi!$B$17=""),"",Venturi!$B$17),Propiedades!$B$13)) | N25: =IF(OR(H25="",H25<=0),"",PI()*(H25/1000)^2/4) | O25: =IF(OR(K25="",N25="",N25=0),"",K25/60000/N25) | P25: =IF(OR(L25="",O25="",H25="",M25="",M25=0),"",L25*O25*(H25/1000)/M25) | Q25: =IF(OR(I25="",H25="",H25=0),"",I25/H25) | R25: =IF(OR(P25="",P25<=0,H25="",H25<=0,I25=""),"",IF(P25<2300,64/P25,0.25/(LOG10(I25/(3.7*H25)+5.74/(P25^0.9))^2))) | S25: =IF(OR(G25="",H25="",H25<=0,R25="",O25=""),"",R25*(G25/(H25/1000))*O25^2/(2*Datos_base!$B$6)) | T25: =IF(OR(J25="",O25=""),"",J25*O25^2/(2*Datos_base!$B$6)) | U25: =IF(OR(L25="",O25="",S25="",T25=""),"",L25*Datos_base!$B$6*(S25+T25)/1000) | V25: =IF(OR($B25="",$C25=""),"",IF(AND($G25<>"",$H25<>"",$I25<>""),"OK","INCOMPLETO"))
A26: T-19 | C26: Tramo adicional 12 | J26: 0 | K26: =IF(OR($B26="",$F26=""),"",IF(Datos_base!$B$5="Pistola cerrada",0,IF($F26="Agua",Datos_base!$B$20,IF($F26="Mezcla",Datos_base!$B$22,IF($F26="Químico",Datos_base!$B$21,""))))) | L26: =IF(OR($B26="",$F26=""),"",IF($F26="Químico",IF(OR(Datos_base!$B$21="",Datos_base!$B$21=0,Venturi!$B$16=""),"",Venturi!$B$16),Propiedades!$B$12)) | M26: =IF(OR($B26="",$F26=""),"",IF($F26="Químico",IF(OR(Datos_base!$B$21="",Datos_base!$B$21=0,Venturi!$B$17=""),"",Venturi!$B$17),Propiedades!$B$13)) | N26: =IF(OR(H26="",H26<=0),"",PI()*(H26/1000)^2/4) | O26: =IF(OR(K26="",N26="",N26=0),"",K26/60000/N26) | P26: =IF(OR(L26="",O26="",H26="",M26="",M26=0),"",L26*O26*(H26/1000)/M26) | Q26: =IF(OR(I26="",H26="",H26=0),"",I26/H26) | R26: =IF(OR(P26="",P26<=0,H26="",H26<=0,I26=""),"",IF(P26<2300,64/P26,0.25/(LOG10(I26/(3.7*H26)+5.74/(P26^0.9))^2))) | S26: =IF(OR(G26="",H26="",H26<=0,R26="",O26=""),"",R26*(G26/(H26/1000))*O26^2/(2*Datos_base!$B$6)) | T26: =IF(OR(J26="",O26=""),"",J26*O26^2/(2*Datos_base!$B$6)) | U26: =IF(OR(L26="",O26="",S26="",T26=""),"",L26*Datos_base!$B$6*(S26+T26)/1000) | V26: =IF(OR($B26="",$C26=""),"",IF(AND($G26<>"",$H26<>"",$I26<>""),"OK","INCOMPLETO"))
A27: T-20 | C27: Tramo adicional 13 | J27: 0 | K27: =IF(OR($B27="",$F27=""),"",IF(Datos_base!$B$5="Pistola cerrada",0,IF($F27="Agua",Datos_base!$B$20,IF($F27="Mezcla",Datos_base!$B$22,IF($F27="Químico",Datos_base!$B$21,""))))) | L27: =IF(OR($B27="",$F27=""),"",IF($F27="Químico",IF(OR(Datos_base!$B$21="",Datos_base!$B$21=0,Venturi!$B$16=""),"",Venturi!$B$16),Propiedades!$B$12)) | M27: =IF(OR($B27="",$F27=""),"",IF($F27="Químico",IF(OR(Datos_base!$B$21="",Datos_base!$B$21=0,Venturi!$B$17=""),"",Venturi!$B$17),Propiedades!$B$13)) | N27: =IF(OR(H27="",H27<=0),"",PI()*(H27/1000)^2/4) | O27: =IF(OR(K27="",N27="",N27=0),"",K27/60000/N27) | P27: =IF(OR(L27="",O27="",H27="",M27="",M27=0),"",L27*O27*(H27/1000)/M27) | Q27: =IF(OR(I27="",H27="",H27=0),"",I27/H27) | R27: =IF(OR(P27="",P27<=0,H27="",H27<=0,I27=""),"",IF(P27<2300,64/P27,0.25/(LOG10(I27/(3.7*H27)+5.74/(P27^0.9))^2))) | S27: =IF(OR(G27="",H27="",H27<=0,R27="",O27=""),"",R27*(G27/(H27/1000))*O27^2/(2*Datos_base!$B$6)) | T27: =IF(OR(J27="",O27=""),"",J27*O27^2/(2*Datos_base!$B$6)) | U27: =IF(OR(L27="",O27="",S27="",T27=""),"",L27*Datos_base!$B$6*(S27+T27)/1000) | V27: =IF(OR($B27="",$C27=""),"",IF(AND($G27<>"",$H27<>"",$I27<>""),"OK","INCOMPLETO"))
A30: RESUMEN DE PÉRDIDAS / COMPLETITUD
A31: Pérdida total en succión | B31: =SUMIF($B$8:$B$27,"Succión",$U$8:$U$27) -> 0.38888478 | C31: kPa
A32: Pérdida total antes del Venturi | B32: =SUMIF($B$8:$B$27,"Antes Venturi",$U$8:$U$27) -> 0 | C32: kPa
A33: Pérdida total después del Venturi | B33: =SUMIF($B$8:$B$27,"Después Venturi",$U$8:$U$27) -> 1.0759146 | C33: kPa
A34: Pérdida de la línea química | B34: =SUMIF($B$8:$B$27,"Químicos",$U$8:$U$27) -> 0 | C34: kPa
A35: N.º de tramos incompletos en circuitos activos | B35: =COUNTIFS($B$8:$B$27,"Succión",$V$8:$V$27,"INCOMPLETO")+COUNTIFS($B$8:$B$27,"Antes Venturi",$V$8:$V$27,"INCOMPLETO")+COUNTIFS($B$8:$B$27,"Después Venturi",$V$8:$V$27,"INCOMPLETO")+IF(OR(Datos_base!$B$5="Prelavado",Datos_base!$B$5="Jabón",Datos_base!$B$5="Cera"),COUNTIFS($B$8:$B$27,"Químicos",$V$8:$V$27,"INCOMPLETO"),0) -> 0 | C35: conteo de celdas
A36: Estado de geometría de circuitos activos | B36: =IF(B35=0,"GEOMETRÍA DECLARADA PARA TRAMOS ACTIVOS","PENDIENTE: completar longitud, diámetro interno y rugosidad") -> GEOMETRÍA DECLARADA PARA TRAMOS ACTIVOS | C36: —
A37: N.º de tramos incompletos en succión | B37: =COUNTIFS($B$8:$B$27,"Succión",$V$8:$V$27,"INCOMPLETO") -> 0 | C37: conteo de celdas
A38: Estado de geometría de succión | B38: =IF(B37=0,"SUCCIÓN OK","PENDIENTE: completar geometría de succión") -> SUCCIÓN OK | C38: —
A39: N.º de tramos incompletos en recorrido de presión | B39: =COUNTIFS($B$8:$B$27,"Antes Venturi",$V$8:$V$27,"INCOMPLETO")+COUNTIFS($B$8:$B$27,"Después Venturi",$V$8:$V$27,"INCOMPLETO") -> 0 | C39: conteo de celdas
A40: Estado de geometría del recorrido de presión | B40: =IF(B39=0,"RECORRIDO DE PRESIÓN OK","PENDIENTE: completar geometría antes/después Venturi") -> RECORRIDO DE PRESIÓN OK | C40: —

Sheet Alimentacion
A1: ALIMENTACIÓN, FILTRO, CALENTADOR Y SUCCIÓN DE BOMBA
A2: Presión en brida de succión y NPSH disponible. Los datos del filtro y calentador son entradas necesarias porque sus pérdidas deben restarse de la presión de acometida.
A4: Parámetro / resultado | B4: Valor | C4: Unidad | D4: Tipo | E4: Observación
A5: Presión dinámica de acometida | B5: =IF(Datos_base!B8="","",Datos_base!B8) -> 1.5 | C5: bar(g) | D5: Calculado / vínculo | E5: Debe medirse en operación.
A6: Pérdida de presión del filtro | B6: 0 | C6: kPa | D6: Entrada requerida | E6: Usar curva fabricante al caudal actual y contemplar condición de filtro cargado.
A7: Pérdida de presión del calentador | B7: 0 | C7: kPa | D7: Entrada requerida | E7: Solicitar del proveedor a caudal de diseño.
A8: Pérdida total de tubería en succión | B8: =IF(Tuberias!$B$38<>"SUCCIÓN OK","",Tuberias!$B$31) -> 0.38888478 | C8: kPa | D8: Calculado | E8: Suma de pérdidas en los tramos identificados como Succión.
A9: Diferencia de cota fuente − succión | B9: =Datos_base!B13 -> 0.5 | C9: m | D9: Calculado / vínculo | E9: Positiva cuando la fuente está por encima de la brida de succión.
A10: Temperatura de entrada | B10: =Datos_base!B9 -> 15 | C10: °C | D10: Calculado / vínculo | E10: Temperatura medida en acometida.
A11: Temperatura estimada en succión | B11: =Datos_base!B23 -> 40 | C11: °C | D11: Calculado / vínculo | E11: Debe ser compatible con la bomba; ver alerta térmica.
A12: Presión absoluta en brida de succión | B12: =IF(OR(B5="",B6="",B7="",B8="",Propiedades!$B$12="",Tuberias!$B$38<>"SUCCIÓN OK"),"",Datos_base!$B$7+B5*100-B6-B7-B8+Propiedades!$B$12*Datos_base!$B$6*B9/1000) -> 228.47809 | C12: kPa(abs) | D12: Calculado | E12: Patm + presión dinámica manométrica − pérdidas + corrección de cota.
A13: Velocidad en tramo final de succión | B13: =IF(Tuberias!$B$38<>"SUCCIÓN OK","",Tuberias!$O$10) -> 0.40932375 | C13: m/s | D13: Calculado | E13: Vinculada al tramo T-03; verificar que la geometría esté completada.
A14: NPSH disponible | B14: =IF(OR(B12="",B13="",Propiedades!$B$14="",Propiedades!$B$12=""),"",((B12-Propiedades!$B$14)*1000/(Propiedades!$B$12*Datos_base!$B$6))+(B13^2/(2*Datos_base!$B$6))) -> 22.724884 | C14: m | D14: Calculado | E14: (Pabs,s − Pvap)/(rho·g) + v²/(2g), con presión absoluta en la brida de succión.
A15: NPSHr de bomba | B15: =IF(Bomba!B13="","",Bomba!B13) -> 3 | C15: m | D15: Calculado / vínculo | E15: Se necesita dato del fabricante; puede no estar publicado para el equipo completo.
A16: Diferencia NPSHa − NPSHr | B16: =IF(OR(B14="",B15=""),"",B14-B15) -> 19.724884 | C16: m | D16: Calculado | E16: Margen bruto; todavía falta comparar contra la reserva de diseño.
A17: Reserva NPSH de diseño | B17: =IF(Datos_base!B15="","",Datos_base!B15) -> 3 | C17: m | D17: Calculado / vínculo | E17: Definir un criterio con fabricante / diseño.
A18: Margen neto: NPSHa − NPSHr − reserva | B18: =IF(OR(B14="",B15="",B17=""),"",B14-B15-B17) -> 16.724884 | C18: m | D18: Calculado | E18: Debe ser positivo y cumplir los criterios técnicos aplicables.
A19: Estado preliminar NPSH | B19: =IF(B14="","PENDIENTE: completar presión, pérdidas y geometría de succión",IF(B15="","PENDIENTE: NPSHr fabricante",IF(B17="","PENDIENTE: definir reserva de diseño",IF(B18>0,"CUMPLE CRITERIO PRELIMINAR","NO CUMPLE / REVISAR DISEÑO")))) -> CUMPLE CRITERIO PRELIMINAR | C19: — | D19: Calculado | E19: No dar por verificado hasta contar con NPSHr y geometría real.
A20: Caudal másico de agua | B20: =IF(OR(Datos_base!B20="",Propiedades!B7=""),"",Datos_base!B20/60000*Propiedades!B7) -> 0.116565 | C20: kg/s | D20: Calculado | E20: Para cálculo térmico.
A21: Potencia térmica requerida para elevar T | B21: =IF(OR(B20="",Datos_base!B12="",Datos_base!B9=""),"",MAX(0,B20*Datos_base!B11*(Datos_base!B12-Datos_base!B9))) -> 12181.042 | C21: W | D21: Calculado | E21: mdot·cp·max(0, T_objetivo − T_entrada); no incluye pérdidas térmicas del equipo.
A22: Potencia térmica nominal del calentador | B22: =IF(Datos_base!B16="","",Datos_base!B16) -> 12 | C22: kW | D22: Calculado / vínculo | E22: Debe corresponder a potencia útil.
A23: Margen de potencia térmica | B23: =IF(OR(B21="",B22=""),"",B22-B21/1000) -> -0.18104222 | C23: kW | D23: Calculado | E23: Potencia nominal menos potencia sensible calculada.

Sheet Manguera_Pistola
A1: MANGUERA DE ALTA PRESIÓN Y PISTOLA
A2: La pérdida de la manguera se calcula en Tuberias. Esta hoja captura la pérdida propia de la pistola y las clasificaciones de presión/temperatura que faltan.
A4: Parámetro / resultado | B4: Valor | C4: Unidad | D4: Tipo | E4: Observación
A5: Manguera alta presión — configuración | B5: Flexible; trazado con pocos cambios de dirección | C5: — | D5: Premisa de diseño | E5: Confirmar radio mínimo de curvatura y evitar dobleces que restrinjan el flujo.
A6: Longitud del tramo después del Venturi | B6: =Tuberias!G12 -> 8 | C6: m | D6: Calculado / vínculo | E6: Se usa Tuberias!G12; actualmente 4 m por la arquitectura preliminar.
A7: Diámetro interno del tramo después del Venturi | B7: =Tuberias!H12 -> 19.05 | C7: mm | D7: Calculado / vínculo | E7: Se usa Tuberias!H12.
A8: Modelo de pistola | B8: 0 | C8: — | D8: Entrada requerida | E8: Marca / referencia de la pistola seleccionada.
A9: Pérdida de presión de pistola abierta | B9: 0 | C9: kPa | D9: Entrada requerida | E9: Curva o presión diferencial medida al caudal de trabajo.
A10: Presión máxima admisible de manguera | B10: 150 | C10: bar(g) | D10: Entrada requerida | E10: Debe superar la presión de diseño con margen aplicable.
A11: Temperatura máxima admisible de manguera | B11: 50 | C11: °C | D11: Entrada requerida | E11: Confirmar compatibilidad con agua, químicos y temperatura de lavado.

Sheet Boquilla
A1: BOQUILLA Y CONDICIÓN DE DESCARGA
A2: La presión requerida en boquilla determina parte sustancial del presupuesto de presión. Preferir curva / tabla de fabricante sobre la aproximación de orificio.
A4: Parámetro / resultado | B4: Valor | C4: Unidad | D4: Tipo | E4: Observación
A5: Método de cálculo | B5: Orificio (Cd) | C5: — | D5: Entrada | E5: Cambie a Curva fabricante cuando disponga de tabla presión–caudal.
A6: Caudal total a boquilla | B6: =Datos_base!B22 -> 7 | C6: L/min | D6: Calculado / vínculo | E6: Agua + producto químico activo.
A7: Densidad de mezcla aproximada | B7: =Propiedades!B12 -> 992.24732 | C7: kg/m³ | D7: Calculado / vínculo | E7: Aproximada con agua; actualizar si la mezcla lo requiere.
A8: Coeficiente de descarga Cd | B8: 0.8 | C8: — | D8: Supuesto inicial | E8: reemplazar con coeficiente/curva del fabricante.
A9: Diámetro efectivo de orificio | B9: 1.15 | C9: mm | D9: Entrada requerida | E9: Boquilla de alta presión
A10: Área geométrica del orificio | B10: =IF(OR(B9="",B9<=0),"",PI()*(B9/1000)^2/4) -> 1.0386891e-06 | C10: m² | D10: Calculado | E10: π·d²/4.
A11: Velocidad media de salida | B11: =IF(OR(B6="",B10="",B10=0),"",B6/60000/B10) -> 112.32107 | C11: m/s | D11: Calculado | E11: Q/A; aproximación de sección circular equivalente.
A12: Presión requerida según orificio | B12: =IF(OR(B6="",B7="",B8="",B10="",B10=0),"",((B7/2)*(B6/60000/(B8*B10))^2)/100000) -> 97.798551 | C12: bar(g) | D12: Calculado | E12: ρ/2·(Q/(Cd·A))²; modelo idealizado de orificio.
A13: Presión a caudal objetivo según fabricante | B13: 0 | C13: bar(g) | D13: Entrada requerida | E13: Completar solo cuando se use el método Curva fabricante.
A14: Presión requerida seleccionada | B14: =IF(B5="Orificio (Cd)",B12,IF(B5="Curva fabricante",B13,"")) -> 97.798551 | C14: bar(g) | D14: Calculado | E14: Fuente para balance total de presión de la red.
A15: Presión máxima admisible de la boquilla | B15: 0 | C15: bar(g) | D15: Entrada requerida | E15: Verificar compatibilidad con presión disponible y química.
A16: Caudal nominal de boquilla | B16: 7 | C16: L/min | D16: Entrada requerida | E16: Comparar con el caudal calculado y la curva de la bomba.

Sheet Resumen
A1: RESUMEN INTEGRADO DE LA MEMORIA HIDRÁULICA
A2: Salidas preliminares del modo activo. Los resultados integrados de presión quedan en blanco hasta completar las entradas necesarias; los datos publicados de TRENT se usan solo como referencia.
A4: Indicador | B4: Resultado | C4: Unidad | D4: Criterio / lectura | E4: Estado / observación
A5: Modo activo | B5: =Datos_base!B5 -> Enjuague | C5: — | D5: Escenario elegido | E5: Cambie Datos_base!B5 para estudiar otra etapa.
A6: Caudal de agua activo | B6: =Datos_base!B20 -> 7 | C6: L/min | D6: Caudal que atraviesa bomba | E6: Inicialmente deriva del dato publicado de 7 L/min; confirmar.
A7: Caudal químico activo | B7: =Datos_base!B21 -> 0 | C7: L/min | D7: Caudal aspirado | E7: Solo aplica en Prelavado, Jabón y Cera.
A8: Caudal de mezcla | B8: =Datos_base!B22 -> 7 | C8: L/min | D8: Caudal total aguas abajo del Venturi | E8: Incluye producto si está activado.
A9: Temperatura de entrada | B9: =Datos_base!B9 -> 15 | C9: °C | D9: Frontera térmica | E9: Supuesto inicial editable.
A10: Temperatura objetivo de calentador | B10: =IF(Datos_base!B12="","",Datos_base!B12) -> 40 | C10: °C | D10: Requerimiento térmico | E10: No autoriza calentar antes de la HLT395.
A11: Potencia térmica requerida | B11: =IF(Alimentacion!B21="","",Alimentacion!B21/1000) -> 12.181042 | C11: kW | D11: Potencia sensible mínima | E11: No incluye pérdidas ni eficiencia del calentador.
A12: Presión requerida en boquilla | B12: =IF(Boquilla!B14="","",Boquilla!B14) -> 97.798551 | C12: bar(g) | D12: Presión para el caudal y boquilla seleccionados | E12: Depende de orificio/Cd o curva de fabricante.
A13: Pérdida de tuberías antes Venturi | B13: =IF(Tuberias!$B$40<>"RECORRIDO DE PRESIÓN OK","",Tuberias!$B$32) -> 0 | C13: kPa | D13: Tramos antes del inyector | E13: Dar geometría a cada tramo.
A14: Pérdida del Venturi | B14: =IF(Venturi!B10="","",Venturi!B10) -> 180 | C14: kPa | D14: Componente | E14: Dato de fabricante/ensayo requerido.
A15: Pérdida de tuberías después Venturi | B15: =IF(Tuberias!$B$40<>"RECORRIDO DE PRESIÓN OK","",Tuberias!$B$33) -> 1.0759146 | C15: kPa | D15: Tramos hasta boquilla | E15: Incluye el tramo de manguera de 4 m si se mantiene.
A16: Pérdida de presión de pistola abierta | B16: =IF(Manguera_Pistola!B8="","",Manguera_Pistola!B8) -> 0 | C16: kPa | D16: Componente | E16: Dato de fabricante/ensayo requerido.
A17: Presión requerida a descarga de bomba | B17: =IF(OR(Boquilla!$B$14="",Venturi!$B$10="",Manguera_Pistola!$B$8="",Tuberias!$B$36<>"GEOMETRÍA DECLARADA PARA TRAMOS ACTIVOS",Datos_base!$B$5="Pistola cerrada"),"",Boquilla!$B$14+(Tuberias!$B$32+Tuberias!$B$33+Venturi!$B$10+Manguera_Pistola!$B$8)/100) -> 99.60931 | C17: bar(g) | D17: Balance: p_boquilla + pérdidas aguas abajo | E17: No incluye régimen transitorio de cierre.
A18: Presión requerida con margen | B18: =IF(B17="","",B17*(1+Datos_base!$B$14)) -> 119.53117 | C18: bar(g) | D18: Presión requerida × (1 + margen editable) | E18: Comparación preliminar con la presión nominal publicada.
A19: Presión nominal publicada de hidrolavadora | B19: =Bomba!B7 -> 80 | C19: bar(g) | D19: Dato de referencia | E19: No sustituye la curva Q–P.
A20: Presión máxima publicada de hidrolavadora | B20: =Bomba!B8 -> 130 | C20: bar(g) | D20: Límite reportado | E20: No se considera presión continua de diseño.
A21: Margen frente a presión nominal | B21: =IF(OR(B18="",B19=""),"",B19-B18) -> -39.531172 | C21: bar | D21: Presión nominal − requerida con margen | E21: Debe ser no negativo y luego validarse con la curva oficial.
A22: Estado del presupuesto de presión | B22: =IF(B18="","PENDIENTE: datos de tramos activos, Venturi, pistola y boquilla",IF(B18>B20,"NO CUMPLE: supera presión máxima reportada",IF(B18>B19,"SUPERIOR A PRESIÓN NOMINAL; revisar selección","Dentro de presión nominal publicada; validar curva Q–P"))) -> SUPERIOR A PRESIÓN NOMINAL; revisar selección | C22: — | D22: Comparación preliminar | E22: Solo evaluable tras completar geometría, Venturi, pistola y boquilla.
A23: Presión absoluta estimada a la succión | B23: =Alimentacion!B12 -> 228.47809 | C23: kPa(abs) | D23: Condición de entrada de bomba | E23: Depende de presión real de suministro, pérdidas y desnivel.
A24: NPSH disponible | B24: =Alimentacion!B14 -> 22.724884 | C24: m | D24: Margen frente a presión de vapor | E24: Debe compararse contra NPSHr + reserva de diseño.
A25: NPSHr | B25: =IF(Alimentacion!B15="","",Alimentacion!B15) -> 3 | C25: m | D25: Dato fabricante | E25: Pendiente si no se dispone de valor.
A26: NPSHa − NPSHr − reserva | B26: =Alimentacion!B18 -> 16.724884 | C26: m | D26: Criterio preliminar NPSH | E26: Debe ser positivo con criterio de diseño establecido.
A27: Estado NPSH | B27: =Alimentacion!B19 -> CUMPLE CRITERIO PRELIMINAR | C27: — | D27: Ver Alimentacion | E27: No considerarlo verificado sin datos del fabricante.
A28: Estado de geometría activa | B28: =Tuberias!B36 -> GEOMETRÍA DECLARADA PARA TRAMOS ACTIVOS | C28: — | D28: Ver Tuberias | E28: Completar longitudes, diámetros y rugosidad.

Sheet Estaciones
A1: ESTACIONES DE CÁLCULO Y VARIABLES DEL FLUJO
A2: Mapa de nodos para conectar los balances. Presiones de descarga basadas en valores publicados son referencias provisionales; las presiones locales del Venturi exigen datos o mediciones.
A4: ID | B4: Estación | C4: Fluido | D4: P manométrica (bar) | E4: P absoluta (kPa) | F4: T (°C) | G4: Q (L/min) | H4: rho (kg/m³) | I4: A / Diám. dato | J4: v (m/s) | K4: z relativa (m) | L4: Fuente / estado
A5: N0 | B5: Acometida antes de tubería/filtro | C5: Agua | D5: =IF(Datos_base!B8="","",Datos_base!B8) -> 1.5 | E5: =IF(D5="","",Datos_base!B7+D5*100) -> 224 | F5: =Datos_base!B9 -> 15 | G5: =Datos_base!B20 -> 7 | H5: =Propiedades!B7 -> 999.12855 | I5: T-01 | J5: =Tuberias!O8 -> 0.40932375 | K5: 0 | L5: Presión dinámica de entrada medida.
A6: N1 | B6: Salida de filtro | C6: Agua | D6: =IF(E6="","",(E6-Datos_base!B7)/100) -> 1.4987037 | E6: =IF(OR(E5="",Tuberias!U8="",Alimentacion!B6=""),"",E5-Tuberias!U8-Alimentacion!B6) -> 223.87037 | F6: =Datos_base!B9 -> 15 | G6: =Datos_base!B20 -> 7 | H6: =Propiedades!B7 -> 999.12855 | I6: T-02 | J6: =Tuberias!O9 -> 0.40932375 | L6: Restar pérdida de T-01 y del filtro.
A7: N2 | B7: Salida calentador / brida succión bomba | C7: Agua | D7: =IF(E7="","",(E7-Datos_base!B7)/100) -> 1.5447809 | E7: =Alimentacion!B12 -> 228.47809 | F7: =Datos_base!B23 -> 40 | G7: =Datos_base!B20 -> 7 | H7: =Propiedades!B12 -> 992.24732 | I7: T-03 | J7: =Tuberias!O10 -> 0.40932375 | L7: Condición crítica para NPSH; temperatura compatible obligatoria.
A8: N3 | B8: Descarga de bomba | C8: Agua | D8: =Bomba!B7 -> 80 | E8: =IF(D8="","",Datos_base!B7+D8*100) -> 8074 | F8: =Datos_base!B23 -> 40 | G8: =Datos_base!B20 -> 7 | H8: =Propiedades!B12 -> 992.24732 | I8: T-04 | J8: =Tuberias!O11 -> 0.40932375 | L8: Presión nominal publicada usada como referencia; falta curva Q–P.
A9: Nt | B9: Garganta / puerto de aspiración Venturi | C9: Agua + químico aspirado | D9: =IF(Venturi!B18="","",Venturi!B18) -> -0.288 | E9: =IF(D9="","",Datos_base!B7+D9*100) -> 45.2 | F9: =Datos_base!B23 -> 40 | G9: =Datos_base!B20 -> 7 | H9: =Propiedades!B12 -> 992.24732 | I9: Geometría no definida | L9: Presión de garganta por fabricante o medición; no calculada idealmente.
A10: N4 | B10: Salida Venturi / mezcla | C10: Mezcla | D10: =Venturi!B20 -> 78.2 | E10: =IF(D10="","",Datos_base!B7+D10*100) -> 7894 | F10: =Datos_base!B23 -> 40 | G10: =Datos_base!B22 -> 7 | H10: =Propiedades!B12 -> 992.24732 | I10: T-05 | J10: =Tuberias!O12 -> 0.40932375 | L10: Presión estimada = entrada Venturi menos ΔP de inyector.
